Workbook

Sheet Summary
A1: DFAT PNG Housing - Project 2- PTE
B3: SUMMARY
A4: Code | B4: Description | C4: Total
A5: 1 | B5: Stage 2 | C5: =C10+C9+C8+C7+C6 -> 0
B6: H35 | C6: ='H13, H16, H35'!F214 -> 0
B7: H36 | C7: ='H4, H14, H15, H36, H37, H38,H39'!F213 -> 0
B8: H37 | C8: ='H4, H14, H15, H36, H37, H38,H39'!F213 -> 0
B9: H38 | C9: ='H4, H14, H15, H36, H37, H38,H39'!F213 -> 0
B10: H39 | C10: ='H4, H14, H15, H36, H37, H38,H39'!F213 -> 0
A12: 2 | B12: Stage 3 | C12: =SUM(C13:C18) -> 0
B13: H29 | C13: ='H25, H29'!F209 -> 0
B14: H30 | C14: ='H19, H30'!F209 -> 0
B15: H31 | C15: ='H18, H23, H31'!F209 -> 0
B16: H32 | C16: ='H28, H32'!F209 -> 0
B17: H33 | C17: ='H22, H33'!F209 -> 0
B18: H34 | C18: ='H21, H34, H26'!F209 -> 0
A20: 3 | B20: Stage 4 | C20: =SUM(C21:C26) -> 0
B21: H23 | C21: ='H18, H23, H31'!F209 -> 0
B22: H24 | C22: ='H24, H17'!F209 -> 0
B23: H25 | C23: ='H25, H29'!F209 -> 0
B24: H26 | C24: ='H21, H34, H26'!F209 -> 0
B25: H27 | C25: ='H20, H27'!F209 -> 0
B26: H28 | C26: ='H28, H32'!F209 -> 0
A28: 4 | B28: Stage 5 | C28: =SUM(C29:C32) -> 0
B29: H13 | C29: ='H13, H16, H35'!F214 -> 0
B30: H14 | C30: ='H4, H14, H15, H36, H37, H38,H39'!F213 -> 0
B31: H15 | C31: ='H4, H14, H15, H36, H37, H38,H39'!F213 -> 0
B32: H16 | C32: ='H13, H16, H35'!F214 -> 0
A34: 5 | B34: Stage 6 | C34: =SUM(C35:C40) -> 0
B35: H17 | C35: ='H24, H17'!F209 -> 0
B36: H18 | C36: ='H18, H23, H31'!F209 -> 0
B37: H19 | C37: ='H19, H30'!F209 -> 0
B38: H20 | C38: ='H20, H27'!F209 -> 0
B39: H21 | C39: ='H21, H34, H26'!F209 -> 0
B40: H22 | C40: ='H22, H33'!F209 -> 0
A42: 6 | B42: Stage 7 | C42: =SUM(C43:C48) -> 0
B43: H1 | C43: ='H1, H2, H7, H8'!F211 -> 0
B44: H2 | C44: ='H1, H2, H7, H8'!F211 -> 0
B45: H3 | C45: ='H3'!F212 -> 0
B46: H4 | C46: ='H4, H14, H15, H36, H37, H38,H39'!F213 -> 0
...

Sheet Work Rates
C1: Day Work Rates
C3: Description | D3: Hourly Rate | E3: Daily Rate
B4: 1 | C4: Contract manager | D4: [AUD or PCK] | E4: [AUD or PCK]
B5: 2 | C5: Project manager | D5: [AUD or PCK] | E5: [AUD or PCK]
B6: 3 | C6: WHS manager | D6: [AUD or PCK] | E6: [AUD or PCK]
B7: 4 | C7: Foreman | D7: [AUD or PCK] | E7: [AUD or PCK]
B8: 5 | C8: Unskilled Labour | D8: [AUD or PCK] | E8: [AUD or PCK]
B9: 6 | C9: Electrician | D9: [AUD or PCK] | E9: [AUD or PCK]
B10: 7 | C10: Plumber | D10: [AUD or PCK] | E10: [AUD or PCK]
B11: 8 | C11: Mechanical Technician | D11: [AUD or PCK] | E11: [AUD or PCK]
B12: 9 | C12: Carpenter | D12: [AUD or PCK] | E12: [AUD or PCK]
B13: 10 | C13: Plasterer | D13: [AUD or PCK] | E13: [AUD or PCK]
B14: 11 | C14: Painter | D14: [AUD or PCK] | E14: [AUD or PCK]
B15: 12 | C15: Tiler | D15: [AUD or PCK] | E15: [AUD or PCK]
B16: 13 | C16: [insert additional rows as required] | D16: [AUD or PCK] | E16: [AUD or PCK]

Sheet H1, H2, H7, H8
A1: DFAT PNG Housing - H1, H2, H7, H8 - PTE
A3: Code | B3: Description | C3: Quantity | D3: UOM | E3: Rate | F3: Total
B5: BUILDING TYPES
A6: 1 | B6: H1, H2, H7, H8
B8: 4 BEDROOM APARTMENT
A10: 1.1 | B10: Demolition
B11: DEMOLITION
B12: Preamble
B13: Rate include disposal of demolition debris | D13: note
B14: Protection
A15: 1.1.1 | B15: Protection of the existing doors and architrave during construction | C15: 15 | D15: no | F15: =C15*E15 -> 0
A16: 1.1.2 | B16: Remove/store the reusable items | C16: 1 | D16: Item | F16: =C16*E16 -> 0
B17: Services Protection
A18: 1.1.3 | B18: Terminating redundant services and capping of existing services including light switches, GPO's Data outlets, TV outlets | C18: 1 | D18: Item | F18: =C18*E18 -> 0
B19: Demolition
A20: 1.1.4 | B20: Removal and disposal of existing joinery and accessories | C20: 8 | D20: m | F20: =C20*E20 -> 0
A21: 1.1.5 | B21: Removal and disposal of existing partition | C21: 8 | D21: m2 | F21: =C21*E21 -> 0
A22: 1.1.6 | B22: Removal and disposal of plasterboard cladding in all existing wardrobes, and make good for new fibre cement sheet | C22: 36 | D22: m2 | F22: =C22*E22 -> 0
A23: 1.1.7 | B23: Removal and disposal of existing wardrobe | C23: 12 | D23: m | F23: =C23*E23 -> 0
A24: 1.1.8 | B24: Removal and disposal of existing door furniture | C24: 13 | D24: no | F24: =C24*E24 -> 0
A25: 1.1.9 | B25: Removal and disposal of existing stair treads, handrail & balustrade | C25: 9 | D25: m | F25: =C25*E25 -> 0
A26: 1.1.10 | B26: Removal and disposal of existing floor finishes | C26: 145 | D26: m2 | F26: =C26*E26 -> 0
A27: 1.1.11 | B27: Removal and disposal of existing shower base | C27: 2 | D27: no | F27: =C27*E27 -> 0
A28: 1.1.12 | B28: Removal and disposal of bath & toilet pan | C28: 1 | D28: item | F28: =C28*E28 -> 0
A29: 1.1.13 | B29: Removal and disposal of existing doors | C29: 1 | D29: no | F29: =C29*E29 -> 0
A30: 1.1.14 | B30: Removal and disposal existing wall tiling | C30: 86 | D30: m2 | F30: =C30*E30 -> 0
A31: 1.1.15 | B31: Removal and disposal internal distribution boards | C31: 1 | D31: no | F31: =C31*E31 -> 0
... A33: 1.1.17 | B33: Removal and disposal of all existing external perimeter windows and security grill including Making good of existing window flashing and DPC's | C33: 56 | D33: m2 | F33: =C33*E33 -> 0
B34: Miscellaneous | F34: =C34*E34 -> 0
A35: 1.1.19 | B35: Removal and disposal of existing general power, wiring, smoke alarms and any other unmeasured items | C35: 1 | D35: Item | F35: =C35*E35 -> 0
A36: 1.1.20 | B36: Removal and disposal of existing lights | C36: 1 | D36: item | F36: =C36*E36 -> 0
A37: 1.1.21 | B37: Removal and disposal all existing ceiling fans, associated controls and make good ceiling | C37: 1 | D37: item | F37: =C37*E37 -> 0
A38: 1.1.22 | B38: All emergency key fittings to be removed | C38: 1 | D38: item | F38: =C38*E38 -> 0
B39: TOTAL Demolition | F39: =SUM(F15:F38) -> 0
A41: 1.2 | B41: Wall Finishes/Painting
B42: WALL FINISHES/PAINTING
B43: Preambles
B44: All existing internal walls to be repainted or retiled as applicable, following completion of all patching and surface preparation works. | D44: note
B45: Internal wall surfaces to be prepared to receive new finishes, including filling, sanding, and priming as required. | D45: note
B46: Ceiling painting is excluded from this section and is addressed under Ceiling Finishes | D46: note
...

Sheet H3
A1: DFAT PNG Housing - H3 - PTE
A3: Code | B3: Description | C3: Quantity | D3: UOM | E3: Rate | F3: Total
B5: BUILDING TYPES
A6: 2 | B6: H3
B8: 4 BEDROOM APARTMENT
A10: 2.1 | B10: Demolition
B11: DEMOLITION
B12: Preamble
B13: Rate include disposal of demolition debris | D13: note
B14: Protection
A15: 2.1.1 | B15: Protection of the existing doors and architrave during construction | C15: 15 | D15: no | F15: =C15*E15 -> 0
A16: 2.1.2 | B16: Remove/store the reusable items | C16: 1 | D16: Item | F16: =C16*E16 -> 0
B17: Services Protection
A18: 2.1.3 | B18: Terminating redundant services and capping of existing services including light switches, GPO's Data outlets, TV outlets | C18: 1 | D18: Item | F18: =C18*E18 -> 0
B19: Demolition
A20: 2.1.4 | B20: Removal and disposal of existing joinery and accessories | C20: 8 | D20: m | F20: =C20*E20 -> 0
A21: 2.1.5 | B21: Removal and disposal of existing partition | C21: 7 | D21: m2 | F21: =C21*E21 -> 0
A22: 2.1.6 | B22: Removal and disposal of plasterboard cladding in all existing wardrobes, and make good for new fibre cement sheet | C22: 36 | D22: m2 | F22: =C22*E22 -> 0
A23: 2.1.7 | B23: Removal and disposal of existing wardrobe | C23: 12 | D23: m | F23: =C23*E23 -> 0
A24: 2.1.8 | B24: Removal and disposal of existing door furniture | C24: 13 | D24: no | F24: =C24*E24 -> 0
A25: 2.1.9 | B25: Removal and disposal of existing stair treads, handrail & balustrade | C25: 9 | D25: m | F25: =C25*E25 -> 0
A26: 2.1.10 | B26: Removal and disposal of existing floor finishes | C26: 145 | D26: m2 | F26: =C26*E26 -> 0
A27: 2.1.11 | B27: Removal and disposal of existing shower base | C27: 2 | D27: no | F27: =C27*E27 -> 0
A28: 2.1.12 | B28: Removal and disposal of bath & toilet pan | C28: 1 | D28: item | F28: =C28*E28 -> 0
A29: 2.1.13 | B29: Removal and disposal of existing doors | C29: 1 | D29: no | F29: =C29*E29 -> 0
A30: 2.1.14 | B30: Removal and disposal existing wall tiling | C30: 85 | D30: m2 | F30: =C30*E30 -> 0
A31: 2.1.15 | B31: Removal and disposal internal distribution boards | C31: 1 | D31: no | F31: =C31*E31 -> 0
... A33: 2.1.17 | B33: Removal and disposal of all existing external perimeter windows and security grill including Making good of existing window flashing and DPC's | C33: 56 | D33: m2 | F33: =C33*E33 -> 0
B34: Miscellaneous
A35: 2.1.18 | B35: Removal and disposal of existing general power, wiring, smoke alarms and any other unmeasured items | C35: 1 | D35: Item | F35: =C35*E35 -> 0
A36: 2.1.19 | B36: Removal and disposal of existing lights | C36: 1 | D36: item | F36: =C36*E36 -> 0
A37: 2.1.20 | B37: Removal and disposal all existing ceiling fans, associated controls and make good ceiling | C37: 1 | D37: item | F37: =C37*E37 -> 0
A38: 2.1.21 | B38: All emergency key fittings to be removed | C38: 1 | D38: item | F38: =C38*E38 -> 0
B39: TOTAL Demolition | F39: =SUM(F15:F38) -> 0
A41: 2.2 | B41: Wall Finishes/Painting
B42: WALL FINISHES/PAINTING
B43: Preambles
B44: All existing internal walls to be repainted or retiled as applicable, following completion of all patching and surface preparation works. | D44: note
B45: Internal wall surfaces to be prepared to receive new finishes, including filling, sanding, and priming as required. | D45: note
B46: Ceiling painting is excluded from this section and is addressed under Ceiling Finishes | D46: note
...

Sheet H4, H14, H15, H36, H37, H38,H39
A1: DFAT PNG Housing - H4, H 14, H15, H36, H38, H39 PTE
A3: Code | B3: Description | C3: Quantity | D3: UOM | E3: Rate | F3: Total
B5: BUILDING TYPES
A6: 3 | B6: H4, H14, H15, H36, H37, H38, H39
B8: 3 BEDROOM APARTMENT
A10: 3.1 | B10: Demolition
B11: DEMOLITION
B12: Preamble
B13: Rate include disposal of demolition debris | D13: note
B14: Protection
A15: 3.1.1 | B15: Protection of the existing doors and architrave during construction | C15: 15 | D15: no | F15: =C15*E15 -> 0
A16: 3.1.2 | B16: Remove/store the reusable items | C16: 1 | D16: Item | F16: =C16*E16 -> 0
B17: Services Protection
A18: 3.1.3 | B18: Terminating redundant services and capping of existing services including light switches, GPO's Data outlets, TV outlets | C18: 1 | D18: Item | F18: =C18*E18 -> 0
B19: Demolition
A20: 3.1.4 | B20: Removal and disposal of existing joinery and accessories | C20: 8 | D20: m | F20: =C20*E20 -> 0
A21: 3.1.5 | B21: Removal and disposal of existing partition | C21: 6 | D21: m2 | F21: =C21*E21 -> 0
A22: 3.1.6 | B22: Removal and disposal of plasterboard cladding in all existing wardrobes, and make good for new fibre cement sheet | C22: 41 | D22: m2 | F22: =C22*E22 -> 0
A23: 3.1.7 | B23: Removal and disposal of existing wardrobe | C23: 11 | D23: m | F23: =C23*E23 -> 0
A24: 3.1.8 | B24: Removal and disposal of existing door furniture | C24: 13 | D24: no | F24: =C24*E24 -> 0
A25: 3.1.9 | B25: Removal and disposal of existing stair treads, handrail & balustrade | C25: 9 | D25: m | F25: =C25*E25 -> 0
A26: 3.1.10 | B26: Removal and disposal of existing floor finishes | C26: 146 | D26: m2 | F26: =C26*E26 -> 0
A27: 3.1.11 | B27: Removal and disposal of existing shower base | C27: 2 | D27: no | F27: =C27*E27 -> 0
A28: 3.1.12 | B28: Removal and disposal of bath & toilet pan | C28: 1 | D28: item | F28: =C28*E28 -> 0
A29: 3.1.13 | B29: Removal and disposal of existing doors | C29: 1 | D29: no | F29: =C29*E29 -> 0
A30: 3.1.14 | B30: Removal and disposal existing wall tiling | C30: 69 | D30: m2 | F30: =C30*E30 -> 0
A31: 3.1.15 | B31: Removal and disposal internal distribution boards | C31: 1 | D31: no | F31: =C31*E31 -> 0
... A33: 3.1.17 | B33: Removal and disposal of all existing external perimeter windows and security grill including Making good of existing window flashing and DPC's | C33: 51 | D33: m2 | F33: =C33*E33 -> 0
B34: Miscellaneous
A35: 3.1.18 | B35: Removal and disposal of existing general power, wiring, smoke alarms and any other unmeasured items | C35: 1 | D35: Item | F35: =C35*E35 -> 0
A36: 3.1.19 | B36: Removal and disposal of existing lights | C36: 1 | D36: item | F36: =C36*E36 -> 0
A37: 3.1.20 | B37: Removal and disposal all existing ceiling fans, associated controls and make good ceiling | C37: 1 | D37: item | F37: =C37*E37 -> 0
A38: 3.1.21 | B38: All emergency key fittings to be removed | C38: 1 | D38: item | F38: =C38*E38 -> 0
B39: TOTAL Demolition | F39: =SUM(F15:F38) -> 0
A41: 3.2 | B41: Wall Finishes/Painting
B42: WALL FINISHES/PAINTING
B43: Preambles
B44: All existing internal walls to be repainted or retiled as applicable, following completion of all patching and surface preparation works. | D44: note
B45: Internal wall surfaces to be prepared to receive new finishes, including filling, sanding, and priming as required. | D45: note
B46: Ceiling painting is excluded from this section and is addressed under Ceiling Finishes | D46: note
...

Sheet H5
A1: DFAT PNG Housing - H5 - PTE
A3: Code | B3: Description | C3: Quantity | D3: UOM | E3: Rate | F3: Total
B5: BUILDING TYPES
A6: 4 | B6: H5
B8: 4 BEDROOM APARTMENT
A10: 4.1 | B10: Demolition
B11: DEMOLITION
B12: Preamble
B13: Rate include disposal of demolition debris | D13: note
B14: Protection
A15: 4.1.1 | B15: Protection of the existing doors and architrave during construction | C15: 15 | D15: no | F15: =C15*E15 -> 0
A16: 4.1.2 | B16: Remove/store the reusable items | C16: 1 | D16: Item | F16: =C16*E16 -> 0
B17: Services Protection
A18: 4.1.3 | B18: Terminating redundant services and capping of existing services including light switches, GPO's Data outlets, TV outlets | C18: 1 | D18: Item | F18: =C18*E18 -> 0
B19: Demolition
A20: 4.1.4 | B20: Removal and disposal of existing joinery and accessories | C20: 7 | D20: m | F20: =C20*E20 -> 0
A21: 4.1.5 | B21: Removal and disposal of existing partition | C21: 11 | D21: m2 | F21: =C21*E21 -> 0
A22: 4.1.6 | B22: Removal and disposal of plasterboard cladding in all existing wardrobes, and make good for new fibre cement sheet | C22: 35 | D22: m2 | F22: =C22*E22 -> 0
A23: 4.1.7 | B23: Removal and disposal of existing wardrobe | C23: 12 | D23: m | F23: =C23*E23 -> 0
A24: 4.1.8 | B24: Removal and disposal of existing door furniture | C24: 13 | D24: no | F24: =C24*E24 -> 0
A25: 4.1.9 | B25: Removal and disposal of existing stair treads, handrail & balustrade | C25: 9 | D25: m | F25: =C25*E25 -> 0
A26: 4.1.10 | B26: Removal and disposal of existing floor finishes | C26: 156 | D26: m2 | F26: =C26*E26 -> 0
A27: 4.1.11 | B27: Removal and disposal of existing shower base | C27: 2 | D27: no | F27: =C27*E27 -> 0
A28: 4.1.12 | B28: Removal and disposal of bath & toilet pan | C28: 1 | D28: item | F28: =C28*E28 -> 0
A29: 4.1.13 | B29: Removal and disposal of existing doors | C29: 1 | D29: no | F29: =C29*E29 -> 0
A30: 4.1.14 | B30: Removal and disposal existing wall tiling | C30: 88 | D30: m2 | F30: =C30*E30 -> 0
A31: 4.1.15 | B31: Removal and disposal internal distribution boards | C31: 1 | D31: no | F31: =C31*E31 -> 0
... A33: 4.1.17 | B33: Removal and disposal of all existing external perimeter windows and security grill including Making good of existing window flashing and DPC's | C33: 38 | D33: m2 | F33: =C33*E33 -> 0
B34: Miscellaneous
A35: 4.1.18 | B35: Removal and disposal of existing general power, wiring, smoke alarms and any other unmeasured items | C35: 1 | D35: Item | F35: =C35*E35 -> 0
A36: 4.1.19 | B36: Removal and disposal of existing lights | C36: 1 | D36: item | F36: =C36*E36 -> 0
A37: 4.1.20 | B37: Removal and disposal all existing ceiling fans, associated controls and make good ceiling | C37: 1 | D37: item | F37: =C37*E37 -> 0
A38: 4.1.21 | B38: All emergency key fittings to be removed | C38: 1 | D38: item | F38: =C38*E38 -> 0
B39: TOTAL Demolition | F39: =SUM(F15:F38) -> 0
A41: 4.2 | B41: Wall Finishes/Painting
B42: WALL FINISHES/PAINTING
B43: Preambles
B44: All existing internal walls to be repainted or retiled as applicable, following completion of all patching and surface preparation works. | D44: note
B45: Internal wall surfaces to be prepared to receive new finishes, including filling, sanding, and priming as required. | D45: note
B46: Ceiling painting is excluded from this section and is addressed under Ceiling Finishes | D46: note
...

Sheet H6
A1: DFAT PNG Housing - H6 - PTE
A3: Code | B3: Description | C3: Quantity | D3: UOM | E3: Rate | F3: Total
B5: BUILDING TYPES
A6: 5 | B6: H6
B8: 4 BEDROOM APARTMENT
A10: 5.1 | B10: Demolition
B11: DEMOLITION
B12: Preamble
B13: Rate include disposal of demolition debris | D13: note
B14: Protection
A15: 5.1.1 | B15: Protection of the existing doors and architrave during construction | C15: 15 | D15: no | F15: =C15*E15 -> 0
A16: 5.1.2 | B16: Remove/store the reusable items | C16: 1 | D16: Item | F16: =C16*E16 -> 0
B17: Services Protection
A18: 5.1.3 | B18: Terminating redundant services and capping of existing services including light switches, GPO's Data outlets, TV outlets | C18: 1 | D18: Item | F18: =C18*E18 -> 0
B19: Demolition
A20: 5.1.4 | B20: Removal and disposal of existing joinery and accessories | C20: 7 | D20: m | F20: =C20*E20 -> 0
A21: 5.1.5 | B21: Removal and disposal of existing partition | C21: 7 | D21: m2 | F21: =C21*E21 -> 0
A22: 5.1.6 | B22: Removal and disposal of plasterboard cladding in all existing wardrobes, and make good for new fibre cement sheet | C22: 40 | D22: m2 | F22: =C22*E22 -> 0
A23: 5.1.7 | B23: Removal and disposal of existing wardrobe | C23: 11 | D23: m | F23: =C23*E23 -> 0
A24: 5.1.8 | B24: Removal and disposal of existing door furniture | C24: 13 | D24: no | F24: =C24*E24 -> 0
A25: 5.1.9 | B25: Removal and disposal of existing stair treads, handrail & balustrade | C25: 9 | D25: m | F25: =C25*E25 -> 0
A26: 5.1.10 | B26: Removal and disposal of existing floor finishes | C26: 151 | D26: m2 | F26: =C26*E26 -> 0
A27: 5.1.11 | B27: Removal and disposal of existing shower base | C27: 2 | D27: no | F27: =C27*E27 -> 0
A28: 5.1.12 | B28: Removal and disposal of bath & toilet pan | C28: 1 | D28: item | F28: =C28*E28 -> 0
A29: 5.1.13 | B29: Removal and disposal of existing doors | C29: 1 | D29: no | F29: =C29*E29 -> 0
A30: 5.1.14 | B30: Removal and disposal existing wall tiling | C30: 69 | D30: m2 | F30: =C30*E30 -> 0
A31: 5.1.15 | B31: Removal and disposal internal distribution boards | C31: 1 | D31: no | F31: =C31*E31 -> 0
... A33: 5.1.17 | B33: Removal and disposal of all existing external perimeter windows and security grill including Making good of existing window flashing and DPC's | C33: 41 | D33: m2 | F33: =C33*E33 -> 0
B34: Miscellaneous
A35: 5.1.18 | B35: Removal and disposal of existing general power, wiring, smoke alarms and any other unmeasured items | C35: 1 | D35: Item | F35: =C35*E35 -> 0
A36: 5.1.19 | B36: Removal and disposal of existing lights | C36: 1 | D36: item | F36: =C36*E36 -> 0
A37: 5.1.20 | B37: Removal and disposal all existing ceiling fans, associated controls and make good ceiling | C37: 1 | D37: item | F37: =C37*E37 -> 0
A38: 5.1.21 | B38: All emergency key fittings to be removed | C38: 1 | D38: item | F38: =C38*E38 -> 0
B39: TOTAL Demolition | F39: =SUM(F15:F38) -> 0
A41: 5.2 | B41: Wall Finishes/Painting
B42: WALL FINISHES/PAINTING
B43: Preambles
B44: All existing internal walls to be repainted or retiled as applicable, following completion of all patching and surface preparation works. | D44: note
B45: Internal wall surfaces to be prepared to receive new finishes, including filling, sanding, and priming as required. | D45: note
B46: Ceiling painting is excluded from this section and is addressed under Ceiling Finishes | D46: note
...

Sheet H9, H11
A1: DFAT PNG Housing - H9, H11 - PTE
A3: Code | B3: Description | C3: Quantity | D3: UOM | E3: Rate | F3: Total
B5: BUILDING TYPES
A6: 6 | B6: H9, H11
B8: 4 BEDROOM APARTMENT
A10: 6.1 | B10: Demolition
B11: DEMOLITION
B12: Preamble
B13: Rate include disposal of demolition debris | D13: note
B14: Protection
A15: 6.1.1 | B15: Protection of the existing doors and architrave during construction | C15: 15 | D15: no | F15: =C15*E15 -> 0
A16: 6.1.2 | B16: Remove/store the reusable items | C16: 1 | D16: Item | F16: =C16*E16 -> 0
B17: Services Protection
A18: 6.1.3 | B18: Terminating redundant services and capping of existing services including light switches, GPO's Data outlets, TV outlets | C18: 1 | D18: Item | F18: =C18*E18 -> 0
B19: Demolition
A20: 6.1.4 | B20: Removal and disposal of existing joinery and accessories | C20: 7 | D20: m | F20: =C20*E20 -> 0
A21: 6.1.5 | B21: Removal and disposal of existing partition | C21: 7 | D21: m2 | F21: =C21*E21 -> 0
A22: 6.1.6 | B22: Removal and disposal of plasterboard cladding in all existing wardrobes, and make good for new fibre cement sheet | C22: 44 | D22: m2 | F22: =C22*E22 -> 0
A23: 6.1.7 | B23: Removal and disposal of existing wardrobe | C23: 11 | D23: m | F23: =C23*E23 -> 0
A24: 6.1.8 | B24: Removal and disposal of existing door furniture | C24: 13 | D24: no | F24: =C24*E24 -> 0
A25: 6.1.9 | B25: Removal and disposal of existing stair treads, handrail & balustrade | C25: 9 | D25: m | F25: =C25*E25 -> 0
A26: 6.1.10 | B26: Removal and disposal of existing floor finishes | C26: 151 | D26: m2 | F26: =C26*E26 -> 0
A27: 6.1.11 | B27: Removal and disposal of existing shower base | C27: 2 | D27: no | F27: =C27*E27 -> 0
A28: 6.1.12 | B28: Removal and disposal of bath & toilet pan | C28: 1 | D28: item | F28: =C28*E28 -> 0
A29: 6.1.13 | B29: Removal and disposal of existing doors | C29: 1 | D29: no | F29: =C29*E29 -> 0
A30: 6.1.14 | B30: Removal and disposal existing wall tiling | C30: 69 | D30: m2 | F30: =C30*E30 -> 0
A31: 6.1.15 | B31: Removal and disposal internal distribution boards | C31: 1 | D31: no | F31: =C31*E31 -> 0
... A33: 6.1.17 | B33: Removal and disposal of all existing external perimeter windows and security grill including Making good of existing window flashing and DPC's | C33: 44 | D33: m2 | F33: =C33*E33 -> 0
B34: Miscellaneous
A35: 6.1.18 | B35: Removal and disposal of existing general power, wiring, smoke alarms and any other unmeasured items | C35: 1 | D35: Item | F35: =C35*E35 -> 0
A36: 6.1.19 | B36: Removal and disposal of existing lights | C36: 1 | D36: item | F36: =C36*E36 -> 0
A37: 6.1.20 | B37: Removal and disposal all existing ceiling fans, associated controls and make good ceiling | C37: 1 | D37: item | F37: =C37*E37 -> 0
A38: 6.1.21 | B38: All emergency key fittings to be removed | C38: 1 | D38: item | F38: =C38*E38 -> 0
B39: TOTAL Demolition | F39: =SUM(F15:F38) -> 0
A41: 6.2 | B41: Wall Finishes/Painting
B42: WALL FINISHES/PAINTING
B43: Preambles
B44: All existing internal walls to be repainted or retiled as applicable, following completion of all patching and surface preparation works. | D44: note
B45: Internal wall surfaces to be prepared to receive new finishes, including filling, sanding, and priming as required. | D45: note
B46: Ceiling painting is excluded from this section and is addressed under Ceiling Finishes | D46: note
...

Sheet H10, H12
A1: DFAT PNG Housing - H10, H12 - PTE
A3: Code | B3: Description | C3: Quantity | D3: UOM | E3: Rate | F3: Total
B5: BUILDING TYPES
A6: 7 | B6: H10, H12
B8: 4 BEDROOM APARTMENT
A10: 7.1 | B10: Demolition
B11: DEMOLITION
B12: Preamble
B13: Rate include disposal of demolition debris | D13: note
B14: Protection
A15: 7.1.1 | B15: Protection of the existing doors and architrave during construction | C15: 15 | D15: no | F15: =C15*E15 -> 0
A16: 7.1.2 | B16: Remove/store the reusable items | C16: 1 | D16: Item | F16: =C16*E16 -> 0
B17: Services Protection
A18: 7.1.3 | B18: Terminating redundant services and capping of existing services including light switches, GPO's Data outlets, TV outlets | C18: 1 | D18: Item | F18: =C18*E18 -> 0
B19: Demolition
A20: 7.1.4 | B20: Removal and disposal of existing joinery and accessories | C20: 7 | D20: m | F20: =C20*E20 -> 0
A21: 7.1.5 | B21: Removal and disposal of existing partition | C21: 9 | D21: m2 | F21: =C21*E21 -> 0
A22: 7.1.6 | B22: Removal and disposal of plasterboard cladding in all existing wardrobes, and make good for new fibre cement sheet | C22: 36 | D22: m2 | F22: =C22*E22 -> 0
A23: 7.1.7 | B23: Removal and disposal of existing wardrobe | C23: 12 | D23: m | F23: =C23*E23 -> 0
A24: 7.1.8 | B24: Removal and disposal of existing door furniture | C24: 13 | D24: no | F24: =C24*E24 -> 0
A25: 7.1.9 | B25: Removal and disposal of existing stair treads, handrail & balustrade | C25: 9 | D25: m | F25: =C25*E25 -> 0
A26: 7.1.10 | B26: Removal and disposal of existing floor finishes | C26: 161 | D26: m2 | F26: =C26*E26 -> 0
A27: 7.1.11 | B27: Removal and disposal of existing shower base | C27: 2 | D27: no | F27: =C27*E27 -> 0
A28: 7.1.12 | B28: Removal and disposal of bath & toilet pan | C28: 1 | D28: item | F28: =C28*E28 -> 0
A29: 7.1.13 | B29: Removal and disposal of existing doors | C29: 1 | D29: no | F29: =C29*E29 -> 0
A30: 7.1.14 | B30: Removal and disposal existing wall tiling | C30: 72 | D30: m2 | F30: =C30*E30 -> 0
A31: 7.1.15 | B31: Removal and disposal internal distribution boards | C31: 1 | D31: no | F31: =C31*E31 -> 0
... A33: 7.1.17 | B33: Removal and disposal of all existing external perimeter windows and security grill including Making good of existing window flashing and DPC's | C33: 27 | D33: m2 | F33: =C33*E33 -> 0
B34: Miscellaneous
A35: 7.1.18 | B35: Removal and disposal of existing general power, wiring, smoke alarms and any other unmeasured items | C35: 1 | D35: Item | F35: =C35*E35 -> 0
A36: 7.1.19 | B36: Removal and disposal of existing lights | C36: 1 | D36: item | F36: =C36*E36 -> 0
A37: 7.1.20 | B37: Removal and disposal all existing ceiling fans, associated controls and make good ceiling | C37: 1 | D37: item | F37: =C37*E37 -> 0
A38: 7.1.21 | B38: All emergency key fittings to be removed | C38: 1 | D38: item | F38: =C38*E38 -> 0
B39: TOTAL Demolition | F39: =SUM(F15:F38) -> 0
A41: 7.2 | B41: Wall Finishes/Painting
B42: WALL FINISHES/PAINTING
B43: Preambles
B44: All existing internal walls to be repainted or retiled as applicable, following completion of all patching and surface preparation works. | D44: note
B45: Internal wall surfaces to be prepared to receive new finishes, including filling, sanding, and priming as required. | D45: note
B46: Ceiling painting is excluded from this section and is addressed under Ceiling Finishes | D46: note
...

Sheet H13, H16, H35
A1: DFAT PNG Housing - H13, H16, H35 - PTE
A3: Code | B3: Description | C3: Quantity | D3: UOM | E3: Rate | F3: Total
B5: BUILDING TYPES
A6: 8 | B6: H13, H16, H35
B8: 3 BEDROOM APARTMENT
A10: 8.1 | B10: Demolition
B11: DEMOLITION
B12: Preamble
B13: Rate include disposal of demolition debris | D13: note
B14: Protection
A15: 8.1.1 | B15: Protection of the existing doors and architrave during construction | C15: 14 | D15: no | F15: =C15*E15 -> 0
A16: 8.1.2 | B16: Remove/store the reusable items | C16: 1 | D16: Item | F16: =C16*E16 -> 0
B17: Services Protection
A18: 8.1.3 | B18: Terminating redundant services and capping of existing services including light switches, GPO's Data outlets, TV outlets | C18: 1 | D18: Item | F18: =C18*E18 -> 0
B19: Demolition
A20: 8.1.4 | B20: Removal and disposal of existing joinery and accessories | C20: 9 | D20: m | F20: =C20*E20 -> 0
A21: 8.1.5 | B21: Removal and disposal of existing partition | C21: 8 | D21: m2 | F21: =C21*E21 -> 0
A22: 8.1.6 | B22: Removal and disposal of plasterboard cladding in all existing wardrobes, and make good for new fibre cement sheet | C22: 24 | D22: m2 | F22: =C22*E22 -> 0
A23: 8.1.7 | B23: Removal and disposal of existing wardrobe | C23: 10 | D23: m | F23: =C23*E23 -> 0
A24: 8.1.8 | B24: Removal and disposal of existing door furniture | C24: 12 | D24: no | F24: =C24*E24 -> 0
A25: 8.1.9 | B25: Removal and disposal of existing stair treads, handrail & balustrade | C25: 9 | D25: m | F25: =C25*E25 -> 0
A26: 8.1.10 | B26: Removal and disposal of existing floor finishes | C26: 138 | D26: m2 | F26: =C26*E26 -> 0
A27: 8.1.11 | B27: Removal and disposal of existing shower base | C27: 2 | D27: no | F27: =C27*E27 -> 0
A28: 8.1.12 | B28: Removal and disposal of bath & toilet pan | C28: 1 | D28: item | F28: =C28*E28 -> 0
A29: 8.1.13 | B29: Removal and disposal of existing doors | C29: 1 | D29: no | F29: =C29*E29 -> 0
A30: 8.1.14 | B30: Removal and disposal existing wall tiling | C30: 92 | D30: m2 | F30: =C30*E30 -> 0
A31: 8.1.15 | B31: Removal and disposal internal distribution boards | C31: 1 | D31: no | F31: =C31*E31 -> 0
... A33: 8.1.17 | B33: Removal and disposal of all existing external perimeter windows and security grill including Making good of existing window flashing and DPC's | C33: 45 | D33: m2 | F33: =C33*E33 -> 0
B34: Miscellaneous
A35: 8.1.18 | B35: Removal and disposal of existing general power, wiring, smoke alarms and any other unmeasured items | C35: 1 | D35: Item | F35: =C35*E35 -> 0
A36: 8.1.19 | B36: Removal and disposal of existing lights | C36: 1 | D36: item | F36: =C36*E36 -> 0
A37: 8.1.20 | B37: Removal and disposal all existing ceiling fans, associated controls and make good ceiling | C37: 1 | D37: item | F37: =C37*E37 -> 0
A38: 8.1.21 | B38: All emergency key fittings to be removed | C38: 1 | D38: item | F38: =C38*E38 -> 0
B39: TOTAL Demolition | F39: =SUM(F15:F38) -> 0
A41: 8.2 | B41: Wall Finishes/Painting
B42: WALL FINISHES/PAINTING
B43: Preambles
B44: All existing internal walls to be repainted or retiled as applicable, following completion of all patching and surface preparation works. | D44: note
B45: Internal wall surfaces to be prepared to receive new finishes, including filling, sanding, and priming as required. | D45: note
B46: Ceiling painting is excluded from this section and is addressed under Ceiling Finishes | D46: note
...

Sheet H18, H23, H31
A1: DFAT PNG Housing - H18, H23, H31 - PTE
A3: Code | B3: Description | C3: Quantity | D3: UOM | E3: Rate | F3: Total
B5: BUILDING TYPES
A6: 9 | B6: H18, H23, H31
B8: 3 BEDROOM APARTMENT
A10: 9.1 | B10: Demolition
B11: DEMOLITION
B12: Preamble
B13: Rate include disposal of demolition debris | D13: note
B14: Protection
A15: 9.1.1 | B15: Protection of the existing doors and architrave during construction | C15: 14 | D15: no | F15: =C15*E15 -> 0
A16: 9.1.2 | B16: Remove/store the reusable items | C16: 1 | D16: Item | F16: =C16*E16 -> 0
B17: Services Protection
A18: 9.1.3 | B18: Terminating redundant services and capping of existing services including light switches, GPO's Data outlets, TV outlets | C18: 1 | D18: Item | F18: =C18*E18 -> 0
B19: Demolition
A20: 9.1.4 | B20: Removal and disposal of existing joinery and accessories | C20: 11 | D20: m | F20: =C20*E20 -> 0
A21: 9.1.5 | B21: Removal and disposal of existing partition | C21: 6 | D21: m2 | F21: =C21*E21 -> 0
A22: 9.1.6 | B22: Removal and disposal of plasterboard cladding in all existing wardrobes, and make good for new fibre cement sheet | C22: 32 | D22: m2 | F22: =C22*E22 -> 0
A23: 9.1.7 | B23: Removal and disposal of existing wardrobe | C23: 10 | D23: m | F23: =C23*E23 -> 0
A24: 9.1.8 | B24: Removal and disposal of existing door furniture | C24: 13 | D24: no | F24: =C24*E24 -> 0
A25: 9.1.9 | B25: Removal and disposal of existing stair treads, handrail & balustrade | C25: 11 | D25: m | F25: =C25*E25 -> 0
A26: 9.1.10 | B26: Removal and disposal of existing floor finishes | C26: 136 | D26: m2 | F26: =C26*E26 -> 0
A27: 9.1.11 | B27: Removal and disposal of existing shower base | C27: 2 | D27: no | F27: =C27*E27 -> 0
A28: 9.1.12 | B28: Removal and disposal of bath & toilet pan | C28: 1 | D28: item | F28: =C28*E28 -> 0
A29: 9.1.13 | B29: Removal and disposal of existing doors | C29: 1 | D29: no | F29: =C29*E29 -> 0
A30: 9.1.14 | B30: Removal and disposal existing wall tiling | C30: 89 | D30: m2 | F30: =C30*E30 -> 0
A31: 9.1.15 | B31: Removal and disposal internal distribution boards | C31: 1 | D31: no | F31: =C31*E31 -> 0
... A33: 9.1.17 | B33: Removal and disposal of all existing external perimeter windows and security grill including Making good of existing window flashing and DPC's | C33: 44 | D33: m2 | F33: =C33*E33 -> 0
B34: Miscellaneous
A35: 9.1.18 | B35: Removal and disposal of existing general power, wiring, smoke alarms and any other unmeasured items | C35: 1 | D35: Item | F35: =C35*E35 -> 0
A36: 9.1.19 | B36: Removal and disposal of existing lights | C36: 1 | D36: item | F36: =C36*E36 -> 0
A37: 9.1.20 | B37: Removal and disposal all existing ceiling fans, associated controls and make good ceiling | C37: 1 | D37: item | F37: =C37*E37 -> 0
A38: 9.1.21 | B38: All emergency key fittings to be removed | C38: 1 | D38: item | F38: =C38*E38 -> 0
B39: TOTAL Demolition | F39: =SUM(F15:F38) -> 0
A41: 9.2 | B41: Wall Finishes/Painting
B42: WALL FINISHES/PAINTING
B43: Preambles
B44: All existing internal walls to be repainted or retiled as applicable, following completion of all patching and surface preparation works. | D44: note
B45: Internal wall surfaces to be prepared to receive new finishes, including filling, sanding, and priming as required. | D45: note
B46: Ceiling painting is excluded from this section and is addressed under Ceiling Finishes | D46: note
...

Sheet H19, H30
A1: DFAT PNG Housing - H19, H30 - PTE
A3: Code | B3: Description | C3: Quantity | D3: UOM | E3: Rate | F3: Total
B5: BUILDING TYPES
A6: 10 | B6: H19, H30
B8: 3 BEDROOM APARTMENT
A10: 10.1 | B10: Demolition
B11: As insufficient information provided, T&T made the following assumptions to prepare this estimate
B12: Rate include disposal of demolition debris | D12: note
B13: Preamble
B14: Protection
A15: 10.1.1 | B15: Protection of the existing doors and architrave during construction | C15: 14 | D15: no | F15: =C15*E15 -> 0
A16: 10.1.2 | B16: Remove/store the reusable items | C16: 1 | D16: Item | F16: =C16*E16 -> 0
B17: Services Protection
A18: 10.1.3 | B18: Terminating redundant services and capping of existing services including light switches, GPO's Data outlets, TV outlets | C18: 1 | D18: Item | F18: =C18*E18 -> 0
B19: Demolition
A20: 10.1.4 | B20: Removal and disposal of existing joinery and accessories | C20: 10 | D20: m | F20: =C20*E20 -> 0
A21: 10.1.5 | B21: Removal and disposal of existing partition | C21: 6 | D21: m2 | F21: =C21*E21 -> 0
A22: 10.1.6 | B22: Removal and disposal of plasterboard cladding in all existing wardrobes, and make good for new fibre cement sheet | C22: 33 | D22: m2 | F22: =C22*E22 -> 0
A23: 10.1.7 | B23: Removal and disposal of existing wardrobe | C23: 10 | D23: m | F23: =C23*E23 -> 0
A24: 10.1.8 | B24: Removal and disposal of existing door furniture | C24: 12 | D24: no | F24: =C24*E24 -> 0
A25: 10.1.9 | B25: Removal and disposal of existing stair treads, handrail & balustrade | C25: 12 | D25: m | F25: =C25*E25 -> 0
A26: 10.1.10 | B26: Removal and disposal of existing floor finishes | C26: 136 | D26: m2 | F26: =C26*E26 -> 0
A27: 10.1.11 | B27: Removal and disposal of existing shower base | C27: 2 | D27: no | F27: =C27*E27 -> 0
A28: 10.1.12 | B28: Removal and disposal of bath & toilet pan | C28: 1 | D28: item | F28: =C28*E28 -> 0
A29: 10.1.13 | B29: Removal and disposal of existing doors | C29: 1 | D29: no | F29: =C29*E29 -> 0
A30: 10.1.14 | B30: Removal and disposal existing wall tiling | C30: 69 | D30: m2 | F30: =C30*E30 -> 0
A31: 10.1.15 | B31: Removal and disposal internal distribution boards | C31: 1 | D31: no | F31: =C31*E31 -> 0
... A33: 10.1.17 | B33: Removal and disposal of all existing external perimeter windows and security grill including Making good of existing window flashing and DPC's | C33: 44 | D33: m2 | F33: =C33*E33 -> 0
B34: Miscellaneous
A35: 10.1.18 | B35: Removal and disposal of existing general power, wiring, smoke alarms and any other unmeasured items | C35: 1 | D35: Item | F35: =C35*E35 -> 0
A36: 10.1.19 | B36: Removal and disposal of existing lights | C36: 1 | D36: item | F36: =C36*E36 -> 0
A37: 10.1.20 | B37: Removal and disposal all existing ceiling fans, associated controls and make good ceiling | C37: 1 | D37: item | F37: =C37*E37 -> 0
A38: 10.1.21 | B38: All emergency key fittings to be removed | C38: 1 | D38: item | F38: =C38*E38 -> 0
B39: TOTAL Demolition | F39: =SUM(F15:F38) -> 0
A41: 10.2 | B41: Wall Finishes/Painting
B42: WALL FINISHES/PAINTING
B43: Preambles
B44: All existing internal walls to be repainted or retiled as applicable, following completion of all patching and surface preparation works. | D44: note
B45: Internal wall surfaces to be prepared to receive new finishes, including filling, sanding, and priming as required. | D45: note
B46: Ceiling painting is excluded from this section and is addressed under Ceiling Finishes | D46: note
...

Sheet H20, H27
A1: DFAT PNG Housing - H20, H27 - PTE
A3: Code | B3: Description | C3: Quantity | D3: UOM | E3: Rate | F3: Total
B5: BUILDING TYPES
A6: 11 | B6: H20, H27
B8: 4 BEDROOM APARTMENT
A10: 11.1 | B10: Demolition
B11: DEMOLITION
B12: Preamble
B13: Rate include disposal of demolition debris | D13: note
B14: Protection
A15: 11.1.1 | B15: Protection of the existing doors and architrave during construction | C15: 14 | D15: no | F15: =C15*E15 -> 0
A16: 11.1.2 | B16: Remove/store the reusable items | C16: 1 | D16: Item | F16: =C16*E16 -> 0
B17: Services Protection
A18: 11.1.3 | B18: Terminating redundant services and capping of existing services including light switches, GPO's Data outlets, TV outlets | C18: 1 | D18: Item | F18: =C18*E18 -> 0
B19: Demolition
A20: 11.1.4 | B20: Removal and disposal of existing joinery and accessories | C20: 11 | D20: m | F20: =C20*E20 -> 0
A21: 11.1.5 | B21: Removal and disposal of existing partition | C21: 6 | D21: m2 | F21: =C21*E21 -> 0
A22: 11.1.6 | B22: Removal and disposal of plasterboard cladding in all existing wardrobes, and make good for new fibre cement sheet | C22: 48 | D22: m2 | F22: =C22*E22 -> 0
A23: 11.1.7 | B23: Removal and disposal of existing wardrobe | C23: 11 | D23: m | F23: =C23*E23 -> 0
A24: 11.1.8 | B24: Removal and disposal of existing door furniture | C24: 13 | D24: no | F24: =C24*E24 -> 0
A25: 11.1.9 | B25: Removal and disposal of existing stair treads, handrail & balustrade | C25: 9 | D25: m | F25: =C25*E25 -> 0
A26: 11.1.10 | B26: Removal and disposal of existing floor finishes | C26: 155 | D26: m2 | F26: =C26*E26 -> 0
A27: 11.1.11 | B27: Removal and disposal of existing shower base | C27: 2 | D27: no | F27: =C27*E27 -> 0
A28: 11.1.12 | B28: Removal and disposal of bath & toilet pan | C28: 1 | D28: item | F28: =C28*E28 -> 0
A29: 11.1.13 | B29: Removal and disposal of existing doors | C29: 1 | D29: no | F29: =C29*E29 -> 0
A30: 11.1.14 | B30: Removal and disposal existing wall tiling | C30: 72 | D30: m2 | F30: =C30*E30 -> 0
A31: 11.1.15 | B31: Removal and disposal internal distribution boards | C31: 1 | D31: no | F31: =C31*E31 -> 0
... A33: 11.1.17 | B33: Removal and disposal of all existing external perimeter windows and security grill including Making good of existing window flashing and DPC's | C33: 54 | D33: m2 | F33: =C33*E33 -> 0
B34: Miscellaneous
A35: 11.1.18 | B35: Removal and disposal of existing general power, wiring, smoke alarms and any other unmeasured items | C35: 1 | D35: Item | F35: =C35*E35 -> 0
A36: 11.1.19 | B36: Removal and disposal of existing lights | C36: 1 | D36: item | F36: =C36*E36 -> 0
A37: 11.1.20 | B37: Removal and disposal all existing ceiling fans, associated controls and make good ceiling | C37: 1 | D37: item | F37: =C37*E37 -> 0
A38: 11.1.21 | B38: All emergency key fittings to be removed | C38: 1 | D38: item | F38: =C38*E38 -> 0
B39: TOTAL Demolition | F39: =SUM(F15:F38) -> 0
A41: 11.2 | B41: Wall Finishes/Painting
B42: WALL FINISHES/PAINTING
B43: Preambles
B44: All existing internal walls to be repainted or retiled as applicable, following completion of all patching and surface preparation works. | D44: note
B45: Internal wall surfaces to be prepared to receive new finishes, including filling, sanding, and priming as required. | D45: note
B46: Ceiling painting is excluded from this section and is addressed under Ceiling Finishes | D46: note
...

Sheet H21, H34, H26
A1: DFAT PNG Housing - H21, H34, H26 - PTE
A3: Code | B3: Description | C3: Quantity | D3: UOM | E3: Rate | F3: Total
B5: BUILDING TYPES
A6: 12 | B6: H21, H34, H26
B8: 3 BEDROOM APARTMENT
A10: 12.1 | B10: Demolition
B11: DEMOLITION
B12: Preamble
B13: Rate include disposal of demolition debris | D13: note
B14: Protection
A15: 12.1.1 | B15: Protection of the existing doors and architrave during construction | C15: 14 | D15: no | F15: =C15*E15 -> 0
A16: 12.1.2 | B16: Remove/store the reusable items | C16: 1 | D16: Item | F16: =C16*E16 -> 0
B17: Services Protection
A18: 12.1.3 | B18: Terminating redundant services and capping of existing services including light switches, GPO's Data outlets, TV outlets | C18: 1 | D18: Item | F18: =C18*E18 -> 0
B19: Demolition
A20: 12.1.4 | B20: Removal and disposal of existing joinery and accessories | C20: 11 | D20: m | F20: =C20*E20 -> 0
A21: 12.1.5 | B21: Removal and disposal of existing partition | C21: 6 | D21: m2 | F21: =C21*E21 -> 0
A22: 12.1.6 | B22: Removal and disposal of plasterboard cladding in all existing wardrobes, and make good for new fibre cement sheet | C22: 32 | D22: m2 | F22: =C22*E22 -> 0
A23: 12.1.7 | B23: Removal and disposal of existing wardrobe | C23: 10 | D23: m | F23: =C23*E23 -> 0
A24: 12.1.8 | B24: Removal and disposal of existing door furniture | C24: 13 | D24: no | F24: =C24*E24 -> 0
A25: 12.1.9 | B25: Removal and disposal of existing stair treads, handrail & balustrade | C25: 11 | D25: m | F25: =C25*E25 -> 0
A26: 12.1.10 | B26: Removal and disposal of existing floor finishes | C26: 136 | D26: m2 | F26: =C26*E26 -> 0
A27: 12.1.11 | B27: Removal and disposal of existing shower base | C27: 2 | D27: no | F27: =C27*E27 -> 0
A28: 12.1.12 | B28: Removal and disposal of bath & toilet pan | C28: 1 | D28: item | F28: =C28*E28 -> 0
A29: 12.1.13 | B29: Removal and disposal of existing doors | C29: 1 | D29: no | F29: =C29*E29 -> 0
A30: 12.1.14 | B30: Removal and disposal existing wall tiling | C30: 89 | D30: m2 | F30: =C30*E30 -> 0
A31: 12.1.15 | B31: Removal and disposal internal distribution boards | C31: 1 | D31: no | F31: =C31*E31 -> 0
... A33: 12.1.17 | B33: Removal and disposal of all existing external perimeter windows and security grill including Making good of existing window flashing and DPC's | C33: 44 | D33: m2 | F33: =C33*E33 -> 0
B34: Miscellaneous
A35: 12.1.18 | B35: Removal and disposal of existing general power, wiring, smoke alarms and any other unmeasured items | C35: 1 | D35: Item | F35: =C35*E35 -> 0
A36: 12.1.19 | B36: Removal and disposal of existing lights | C36: 1 | D36: item | F36: =C36*E36 -> 0
A37: 12.1.20 | B37: Removal and disposal all existing ceiling fans, associated controls and make good ceiling | C37: 1 | D37: item | F37: =C37*E37 -> 0
A38: 12.1.21 | B38: All emergency key fittings to be removed | C38: 1 | D38: item | F38: =C38*E38 -> 0
B39: TOTAL Demolition | F39: =SUM(F15:F38) -> 0
A41: 12.2 | B41: Wall Finishes/Painting
B42: WALL FINISHES/PAINTING
B43: Preambles
B44: All existing internal walls to be repainted or retiled as applicable, following completion of all patching and surface preparation works. | D44: note
B45: Internal wall surfaces to be prepared to receive new finishes, including filling, sanding, and priming as required. | D45: note
B46: Ceiling painting is excluded from this section and is addressed under Ceiling Finishes | D46: note
...

Sheet H22, H33
A1: DFAT PNG Housing - H22, H33 - PTE
A3: Code | B3: Description | C3: Quantity | D3: UOM | E3: Rate | F3: Total
B5: BUILDING TYPES
A6: 13 | B6: H22, H33
B8: 3 BEDROOM APARTMENT
A10: 13.1 | B10: Demolition
B11: DEMOLITION
B12: Preamble
B13: Rate include disposal of demolition debris | D13: note
B14: Protection
A15: 13.1.1 | B15: Protection of the existing doors and architrave during construction | C15: 14 | D15: no | F15: =C15*E15 -> 0
A16: 13.1.2 | B16: Remove/store the reusable items | C16: 1 | D16: Item | F16: =C16*E16 -> 0
B17: Services Protection
A18: 13.1.3 | B18: Terminating redundant services and capping of existing services including light switches, GPO's Data outlets, TV outlets | C18: 1 | D18: Item | F18: =C18*E18 -> 0
B19: Demolition
A20: 13.1.4 | B20: Removal and disposal of existing joinery and accessories | C20: 10 | D20: m | F20: =C20*E20 -> 0
A21: 13.1.5 | B21: Removal and disposal of existing partition | C21: 6 | D21: m2 | F21: =C21*E21 -> 0
A22: 13.1.6 | B22: Removal and disposal of plasterboard cladding in all existing wardrobes, and make good for new fibre cement sheet | C22: 33 | D22: m2 | F22: =C22*E22 -> 0
A23: 13.1.7 | B23: Removal and disposal of existing wardrobe | C23: 10 | D23: m | F23: =C23*E23 -> 0
A24: 13.1.8 | B24: Removal and disposal of existing door furniture | C24: 12 | D24: no | F24: =C24*E24 -> 0
A25: 13.1.9 | B25: Removal and disposal of existing stair treads, handrail & balustrade | C25: 12 | D25: m | F25: =C25*E25 -> 0
A26: 13.1.10 | B26: Removal and disposal of existing floor finishes | C26: 136 | D26: m2 | F26: =C26*E26 -> 0
A27: 13.1.11 | B27: Removal and disposal of existing shower base | C27: 2 | D27: no | F27: =C27*E27 -> 0
A28: 13.1.12 | B28: Removal and disposal of bath & toilet pan | C28: 1 | D28: item | F28: =C28*E28 -> 0
A29: 13.1.13 | B29: Removal and disposal of existing doors | C29: 1 | D29: no | F29: =C29*E29 -> 0
A30: 13.1.14 | B30: Removal and disposal existing wall tiling | C30: 69 | D30: m2 | F30: =C30*E30 -> 0
A31: 13.1.15 | B31: Removal and disposal internal distribution boards | C31: 1 | D31: no | F31: =C31*E31 -> 0
... A33: 13.1.17 | B33: Removal and disposal of all existing external perimeter windows and security grill including Making good of existing window flashing and DPC's | C33: 44 | D33: m2 | F33: =C33*E33 -> 0
B34: Miscellaneous
A35: 13.1.18 | B35: Removal and disposal of existing general power, wiring, smoke alarms and any other unmeasured items | C35: 1 | D35: Item | F35: =C35*E35 -> 0
A36: 13.1.19 | B36: Removal and disposal of existing lights | C36: 1 | D36: item | F36: =C36*E36 -> 0
A37: 13.1.20 | B37: Removal and disposal all existing ceiling fans, associated controls and make good ceiling | C37: 1 | D37: item | F37: =C37*E37 -> 0
A38: 13.1.21 | B38: All emergency key fittings to be removed | C38: 1 | D38: item | F38: =C38*E38 -> 0
B39: TOTAL Demolition | C39: 194 | D39: m2 | F39: =SUM(F15:F38) -> 0
A41: 13.2 | B41: Wall Finishes/Painting
B42: WALL FINISHES/PAINTING
B43: Preambles
B44: All existing internal walls to be repainted or retiled as applicable, following completion of all patching and surface preparation works. | D44: note
B45: Internal wall surfaces to be prepared to receive new finishes, including filling, sanding, and priming as required. | D45: note
B46: Ceiling painting is excluded from this section and is addressed under Ceiling Finishes | D46: note
...

Sheet H24, H17
A1: DFAT PNG Housing - H24, H 17 - PTE
A3: Code | B3: Description | C3: Quantity | D3: UOM | E3: Rate | F3: Total
B5: BUILDING TYPES
A6: 14 | B6: H24, H17
B8: 4 BEDROOM APARTMENT
A10: 14.1 | B10: Demolition
B11: DEMOLITION
B12: Preamble
B13: Rate include disposal of demolition debris | D13: note
B14: Protection
A15: 14.1.1 | B15: Protection of the existing doors and architrave during construction | C15: 14 | D15: no | F15: =C15*E15 -> 0
A16: 14.1.2 | B16: Remove/store the reusable items | C16: 1 | D16: Item | F16: =C16*E16 -> 0
B17: Services Protection
A18: 14.1.3 | B18: Terminating redundant services and capping of existing services including light switches, GPO's Data outlets, TV outlets | C18: 1 | D18: Item | F18: =C18*E18 -> 0
B19: Demolition
A20: 14.1.4 | B20: Removal and disposal of existing joinery and accessories | C20: 11 | D20: m | F20: =C20*E20 -> 0
A21: 14.1.5 | B21: Removal and disposal of existing partition | C21: 6 | D21: m2 | F21: =C21*E21 -> 0
A22: 14.1.6 | B22: Removal and disposal of plasterboard cladding in all existing wardrobes, and make good for new fibre cement sheet | C22: 48 | D22: m2 | F22: =C22*E22 -> 0
A23: 14.1.7 | B23: Removal and disposal of existing wardrobe | C23: 11 | D23: m | F23: =C23*E23 -> 0
A24: 14.1.8 | B24: Removal and disposal of existing door furniture | C24: 13 | D24: no | F24: =C24*E24 -> 0
A25: 14.1.9 | B25: Removal and disposal of existing stair treads, handrail & balustrade | C25: 9 | D25: m | F25: =C25*E25 -> 0
A26: 14.1.10 | B26: Removal and disposal of existing floor finishes | C26: 155 | D26: m2 | F26: =C26*E26 -> 0
A27: 14.1.11 | B27: Removal and disposal of existing shower base | C27: 2 | D27: no | F27: =C27*E27 -> 0
A28: 14.1.12 | B28: Removal and disposal of bath & toilet pan | C28: 1 | D28: item | F28: =C28*E28 -> 0
A29: 14.1.13 | B29: Removal and disposal of existing doors | C29: 1 | D29: no | F29: =C29*E29 -> 0
A30: 14.1.14 | B30: Removal and disposal existing wall tiling | C30: 72 | D30: m2 | F30: =C30*E30 -> 0
A31: 14.1.15 | B31: Removal and disposal internal distribution boards | C31: 1 | D31: no | F31: =C31*E31 -> 0
... A33: 14.1.17 | B33: Removal and disposal of all existing external perimeter windows and security grill including Making good of existing window flashing and DPC's | C33: 53 | D33: m2 | F33: =C33*E33 -> 0
B34: Miscellaneous
A35: 14.1.18 | B35: Removal and disposal of existing general power, wiring, smoke alarms and any other unmeasured items | C35: 1 | D35: Item | F35: =C35*E35 -> 0
A36: 14.1.19 | B36: Removal and disposal of existing lights | C36: 1 | D36: item | F36: =C36*E36 -> 0
A37: 14.1.20 | B37: Removal and disposal all existing ceiling fans, associated controls and make good ceiling | C37: 1 | D37: item | F37: =C37*E37 -> 0
A38: 14.1.21 | B38: All emergency key fittings to be removed | C38: 1 | D38: item | F38: =C38*E38 -> 0
B39: TOTAL Demolition | F39: =SUM(F15:F38) -> 0
A41: 14.2 | B41: Wall Finishes/Painting
B42: WALL FINISHES/PAINTING
B43: Preambles
B44: All existing internal walls to be repainted or retiled as applicable, following completion of all patching and surface preparation works. | D44: note
B45: Internal wall surfaces to be prepared to receive new finishes, including filling, sanding, and priming as required. | D45: note
B46: Ceiling painting is excluded from this section and is addressed under Ceiling Finishes | D46: note
...

Sheet H25, H29
A1: DFAT PNG Housing - H25, H29 - PTE
A3: Code | B3: Description | C3: Quantity | D3: UOM | E3: Rate | F3: Total
B5: BUILDING TYPES
A6: 15 | B6: H25, H29
B8: 4 BEDROOM APARTMENT
A10: 15.1 | B10: Demolition
B11: DEMOLITION
B12: Preamble
B13: Rate include disposal of demolition debris | D13: note
B14: Protection
A15: 15.1.1 | B15: Protection of the existing doors and architrave during construction | C15: 14 | D15: no | F15: =C15*E15 -> 0
A16: 15.1.2 | B16: Remove/store the reusable items | C16: 1 | D16: Item | F16: =C16*E16 -> 0
B17: Services Protection
A18: 15.1.3 | B18: Terminating redundant services and capping of existing services including light switches, GPO's Data outlets, TV outlets | C18: 1 | D18: Item | F18: =C18*E18 -> 0
B19: Demolition
A20: 15.1.4 | B20: Removal and disposal of existing joinery and accessories | C20: 11 | D20: m | F20: =C20*E20 -> 0
A21: 15.1.5 | B21: Removal and disposal of existing partition | C21: 6 | D21: m2 | F21: =C21*E21 -> 0
A22: 15.1.6 | B22: Removal and disposal of plasterboard cladding in all existing wardrobes, and make good for new fibre cement sheet | C22: 50 | D22: m2 | F22: =C22*E22 -> 0
A23: 15.1.7 | B23: Removal and disposal of existing wardrobe | C23: 11 | D23: m | F23: =C23*E23 -> 0
A24: 15.1.8 | B24: Removal and disposal of existing door furniture | C24: 13 | D24: no | F24: =C24*E24 -> 0
A25: 15.1.9 | B25: Removal and disposal of existing stair treads, handrail & balustrade | C25: 10 | D25: m | F25: =C25*E25 -> 0
A26: 15.1.10 | B26: Removal and disposal of existing floor finishes | C26: 155 | D26: m2 | F26: =C26*E26 -> 0
A27: 15.1.11 | B27: Removal and disposal of existing shower base | C27: 2 | D27: no | F27: =C27*E27 -> 0
A28: 15.1.12 | B28: Removal and disposal of bath & toilet pan | C28: 1 | D28: item | F28: =C28*E28 -> 0
A29: 15.1.13 | B29: Removal and disposal of existing doors | C29: 1 | D29: no | F29: =C29*E29 -> 0
A30: 15.1.14 | B30: Removal and disposal existing wall tiling | C30: 72 | D30: m2 | F30: =C30*E30 -> 0
A31: 15.1.15 | B31: Removal and disposal internal distribution boards | C31: 1 | D31: no | F31: =C31*E31 -> 0
... A33: 15.1.17 | B33: Removal and disposal of all existing external perimeter windows and security grill including Making good of existing window flashing and DPC's | C33: 46 | D33: m2 | F33: =C33*E33 -> 0
B34: Miscellaneous
A35: 15.1.18 | B35: Removal and disposal of existing general power, wiring, smoke alarms and any other unmeasured items | C35: 1 | D35: Item | F35: =C35*E35 -> 0
A36: 15.1.19 | B36: Removal and disposal of existing lights | C36: 1 | D36: item | F36: =C36*E36 -> 0
A37: 15.1.20 | B37: Removal and disposal all existing ceiling fans, associated controls and make good ceiling | C37: 1 | D37: item | F37: =C37*E37 -> 0
A38: 15.1.21 | B38: All emergency key fittings to be removed | C38: 1 | D38: item | F38: =C38*E38 -> 0
B39: TOTAL Demolition | F39: =SUM(F15:F38) -> 0
A41: 15.2 | B41: Wall Finishes/Painting
B42: WALL FINISHES/PAINTING
B43: Preambles
B44: All existing internal walls to be repainted or retiled as applicable, following completion of all patching and surface preparation works. | D44: note
B45: Internal wall surfaces to be prepared to receive new finishes, including filling, sanding, and priming as required. | D45: note
B46: Ceiling painting is excluded from this section and is addressed under Ceiling Finishes | D46: note
...

Sheet Preamble
A1: DFAT PNG Housing - Project 2 - PTE
A3: Code | B3: Description | C3: Unit | D3: Quantity | E3: Rate | F3: Amount
B4: PREAMBLE
B6: Tenderers must provide a full breakdown of the Contract Fixed Lump Sum as a fully costed Bill of Quantities (BOQ). This breakdown is to be provided against the individual items included in a BOQ. This template is an example only and should be adapted to suit the Tenderers needs. This BOQ provides indicative line items and quantities only, Tenderers must undertake their own due diligence when providing their BOQ. - The PDF version of the BOQ must be completed and returned as part of the Tender submission. - The Excel spreadsheet is provided for information and pricing assistance only and does not form part of the Tender submission. | C6: Note
C8: Note
C10: Note
C13: Note

Sheet H28, H32
A1: DFAT PNG Housing - H28, H32 - PTE
A3: Code | B3: Description | C3: Quantity | D3: UOM | E3: Rate | F3: Total
B5: BUILDING TYPES
A6: 16 | B6: H28, H32
B8: 4 BEDROOM APARTMENT
A10: 16.1 | B10: Demolition
B11: DEMOLITION
B12: Preamble
B13: Rate include disposal of demolition debris | D13: note
B14: Protection
A15: 16.1.1 | B15: Protection of the existing doors and architrave during construction | C15: 14 | D15: no | F15: =C15*E15 -> 0
A16: 16.1.2 | B16: Remove/store the reusable items | C16: 1 | D16: Item | F16: =C16*E16 -> 0
B17: Services Protection
A18: 16.1.3 | B18: Terminating redundant services and capping of existing services including light switches, GPO's Data outlets, TV outlets | C18: 1 | D18: Item | F18: =C18*E18 -> 0
B19: Demolition
A20: 16.1.4 | B20: Removal and disposal of existing joinery and accessories | C20: 11 | D20: m | F20: =C20*E20 -> 0
A21: 16.1.5 | B21: Removal and disposal of existing partition | C21: 6 | D21: m2 | F21: =C21*E21 -> 0
A22: 16.1.6 | B22: Removal and disposal of plasterboard cladding in all existing wardrobes, and make good for new fibre cement sheet | C22: 50 | D22: m2 | F22: =C22*E22 -> 0
A23: 16.1.7 | B23: Removal and disposal of existing wardrobe | C23: 11 | D23: m | F23: =C23*E23 -> 0
A24: 16.1.8 | B24: Removal and disposal of existing door furniture | C24: 13 | D24: no | F24: =C24*E24 -> 0
A25: 16.1.9 | B25: Removal and disposal of existing stair treads, handrail & balustrade | C25: 10 | D25: m | F25: =C25*E25 -> 0
A26: 16.1.10 | B26: Removal and disposal of existing floor finishes | C26: 155 | D26: m2 | F26: =C26*E26 -> 0
A27: 16.1.11 | B27: Removal and disposal of existing shower base | C27: 2 | D27: no | F27: =C27*E27 -> 0
A28: 16.1.12 | B28: Removal and disposal of bath & toilet pan | C28: 1 | D28: item | F28: =C28*E28 -> 0
A29: 16.1.13 | B29: Removal and disposal of existing doors | C29: 1 | D29: no | F29: =C29*E29 -> 0
A30: 16.1.14 | B30: Removal and disposal existing wall tiling | C30: 72 | D30: m2 | F30: =C30*E30 -> 0
A31: 16.1.15 | B31: Removal and disposal internal distribution boards | C31: 1 | D31: no | F31: =C31*E31 -> 0
... A33: 16.1.17 | B33: Removal and disposal of all existing external perimeter windows and security grill including Making good of existing window flashing and DPC's | C33: 52 | D33: m2 | F33: =C33*E33 -> 0
B34: Miscellaneous
A35: 16.1.18 | B35: Removal and disposal of existing general power, wiring, smoke alarms and any other unmeasured items | C35: 1 | D35: Item | F35: =C35*E35 -> 0
A36: 16.1.19 | B36: Removal and disposal of existing lights | C36: 1 | D36: item | F36: =C36*E36 -> 0
A37: 16.1.20 | B37: Removal and disposal all existing ceiling fans, associated controls and make good ceiling | C37: 1 | D37: item | F37: =C37*E37 -> 0
A38: 16.1.21 | B38: All emergency key fittings to be removed | C38: 1 | D38: item | F38: =C38*E38 -> 0
B39: TOTAL Demolition | F39: =SUM(F15:F38) -> 0
A41: 16.2 | B41: Wall Finishes/Painting
B42: WALL FINISHES/PAINTING
B43: Preambles
B44: All existing internal walls to be repainted or retiled as applicable, following completion of all patching and surface preparation works. | D44: note
B45: Internal wall surfaces to be prepared to receive new finishes, including filling, sanding, and priming as required. | D45: note
B46: Ceiling painting is excluded from this section and is addressed under Ceiling Finishes | D46: note
...
